// const errormsg = (err) => (
//   err
// )
// const success = (data) => (
//   `${data} Kim`
// )

const errorMsg = (err) => {
  return err
}

const success = (data) => {
  return `${data.name} Kim`
}

// const promise = (data) => {
//   return new Promise ( (resolve, reject) => {
//     let error = `sorry no name is found`
//     if(!data.name) reject(new Error(errorMsg(error)))

//     resolve(success(data))
//   })
// }

//same thing as promise fn? check to see

const asyncFn = async (data) => {
  let error = `sorry not all data is filled out`
  if(!data.name || !data.address || !data.state || !data.city || !data.zip || !data.description || !data.contactEmail)
  return await errorMsg(error)

  let awaitedData = await success(data)
  return awaitedData
}

//if you write async in front of a function, it always returns a promise //wraps non-promises in promises
//await is the same thing as .then waits until the promise settles and returns its result
export const GetUserData = async (data) => {
  try {
    let returnedData = await asyncFn(data)
    console.log(returnedData, 'this is from the try block')
    return returnedData
  }
  catch (err){
    console.log(err)
  }
}